<?xml version="1.0"?>
<robot xmlns:xacro="http://www.ros.org/wiki/xacro">
    <xacro:macro name="base_robot">
        <link name="base_link">
            <visual>
                <geometry>
                    <box size="0.5 0.3 0.1" />
                </geometry>
                <material name="blue">
                    <color rgba="0 0 0.8 1" />
                </material>
            </visual>
            <collision>
                <geometry>
                    <box size="0.5 0.3 0.1" />
                </geometry>
            </collision>
            <inertial>
                <mass value="5" />
                <inertia ixx="0.0395" ixy="0" ixz="0" iyy="0.086" iyz="0" izz="0.1226" />
            </inertial>
        </link>

        <link name="wheel_left">
            <visual>
                <geometry>
                    <cylinder radius="0.1" length="0.05" />
                </geometry>
                <material name="black">
                    <color rgba="0 0 0 1" />
                </material>
            </visual>
            <collision>
                <geometry>
                    <cylinder radius="0.1" length="0.05" />
                </geometry>
            </collision>
            <inertial>
                <mass value="0.5" />
                <inertia ixx="0.00125" ixy="0" ixz="0" iyy="0.00125" iyz="0" izz="0.0025" />
            </inertial>
        </link>

        <joint name="base_to_wheel_left" type="continuous">
            <parent link="base_link" />
            <child link="wheel_left" />
            <origin xyz="-0.15 0.2 -0.05" rpy="${pi/2} 0 0" />
            <axis xyz="0 0 1" />
        </joint>

        <link name="wheel_right">
            <visual>
                <geometry>
                    <cylinder radius="0.1" length="0.05" />
                </geometry>
                <material name="black">
                    <color rgba="0 0 0 1" />
                </material>
            </visual>
            <collision>
                <geometry>
                    <cylinder radius="0.1" length="0.05" />
                </geometry>
            </collision>
            <inertial>
                <mass value="0.5" />
                <inertia ixx="0.00125" ixy="0" ixz="0" iyy="0.00125" iyz="0" izz="0.0025" />
            </inertial>
        </link>

        <joint name="base_to_wheel_right" type="continuous">
            <parent link="base_link" />
            <child link="wheel_right" />
            <origin xyz="-0.15 -0.2 -0.05" rpy="${pi/2} 0 0" />
            <axis xyz="0 0 1" />
        </joint>
    </xacro:macro>
</robot>